Workbook
Name AddInfoCommentBox1: '[1]Library procedures'!#REF!
Name AddInfoCommentBox10: '[1]Library procedures'!#REF!
Name AddInfoCommentBox11: '[1]Library procedures'!#REF!
Name AddInfoCommentBox12: '[1]Library procedures'!#REF!
Name AddInfoCommentBox2: '[1]Library procedures'!#REF!
Name AddInfoCommentBox3: '[1]Library procedures'!#REF!
Name AddInfoCommentBox4: '[1]Library procedures'!#REF!
Name AddInfoCommentBox5: '[1]Library procedures'!#REF!
Name AddInfoCommentBox6: '[1]Library procedures'!#REF!
Name AddInfoCommentBox7: '[1]Library procedures'!#REF!
Name AddInfoCommentBox8: '[1]Library procedures'!#REF!
Name AddInfoCommentBox9: '[1]Library procedures'!#REF!
Name AddInfoName1: '[1]Library procedures'!#REF!
Name AddInfoName10: '[1]Library procedures'!#REF!
Name AddInfoName11: '[1]Library procedures'!#REF!
Name AddInfoName12: '[1]Library procedures'!#REF!
Name AddInfoName2: '[1]Library procedures'!#REF!
Name AddInfoName3: '[1]Library procedures'!#REF!
Name AddInfoName4: '[1]Library procedures'!#REF!
Name AddInfoName5: '[1]Library procedures'!#REF!
Name AddInfoName9: '[1]Library procedures'!#REF!
Name AddInfoTextBox1: '[1]Library procedures'!#REF!
Name AddInfoTextBox10: '[1]Library procedures'!#REF!
Name AddInfoTextBox11: '[1]Library procedures'!#REF!
Name AddInfoTextBox12: '[1]Library procedures'!#REF!
Name AddInfoTextBox2: '[1]Library procedures'!#REF!
Name AddInfoTextBox3: '[1]Library procedures'!#REF!
Name AddInfoTextBox4: '[1]Library procedures'!#REF!
Name AddInfoTextBox5: '[1]Library procedures'!#REF!
Name AddInfoTextBox6: '[1]Library procedures'!#REF!
Name AddInfoTextBox7: '[1]Library procedures'!#REF!
Name AddInfoTextBox8: '[1]Library procedures'!#REF!
Name AddInfoTextBox9: '[1]Library procedures'!#REF!
Name CommentBox1: #REF!
Name CommentBox12a: '[1]Library procedures'!#REF!
Name CommentBox12b: '[1]Library procedures'!#REF!
Name CommentBox12d: '[1]Library procedures'!#REF!
Name CommentBox13a: '[1]Library procedures'!#REF!
Name CommentBox13b: '[1]Library procedures'!#REF!
Name CommentBox13c: '[1]Library procedures'!#REF!
Name CommentBox3b: '[1]Library procedures'!#REF!
Name CommentBox3c: '[1]Library procedures'!#REF!
Name CommentBox4a: '[1]Library procedures'!#REF!
Name CommentBox4b: '[1]Library procedures'!#REF!
Name CommentBox4c: '[1]Library procedures'!#REF!
Name CommentBox4d: '[1]Library procedures'!#REF!
Name CommentBox4e: '[1]Library procedures'!#REF!
Name CommentBox4f: '[1]Library procedures'!#REF!
Name CommentBox7b: '[1]Library procedures'!#REF!
Name CommentBox9a: '[1]Library procedures'!#REF!
Name CommentBox9b: '[1]Library procedures'!#REF!
Name CommentBox9c: '[1]Library procedures'!#REF!
Name Link10d: '[1]Library procedures'!#REF!
Name Link11b: '[1]Library procedures'!#REF!
Name Link11c: '[1]Library procedures'!#REF!
Name Link5b: '[1]Library procedures'!#REF!
Name Link5c: '[1]Library procedures'!#REF!
Name Link8c: '[1]Library procedures'!#REF!
Name Name10a: '[1]Library procedures'!$K$41
Name Name10b: '[1]Library procedures'!$K$42

Sheet Títulos
A1: PASIVOS LABORALES | I1: #VALUE!
A2: EMPRESA | E2: FECHA AUDITORIA
A3: INICIO | B3: 45658 | E3: AUDITOR
A4: CIERRE | B4: =EOMONTH(B3,11) -> 46022 | E4: RESPONSABLE
B8: Avance del Papel de trabajo | C8: =+G8+G11 -> 0 | E8: OK | F8: =+COUNTIF($C$15:$C$26,E8) -> 0 | G8: =+IFERROR(F8/SUM($F$8:$F$11),0) -> 0
E9: EN PROCESO | F9: =+COUNTIF($C$15:$C$26,E9) -> 0 | G9: =+IFERROR(F9/SUM($F$8:$F$11),0) -> 0
E10: PENDIENTE | F10: =+COUNTIF($C$15:$C$26,E10) -> 0 | G10: =+IFERROR(F10/SUM($F$8:$F$11),0) -> 0
E11: N/A | F11: =+COUNTIF($C$15:$C$26,E11) -> 0 | G11: =+IFERROR(F11/SUM($F$8:$F$11),0) -> 0

Sheet PROCEDIMIENTO
A2: PAPEL DE TRABAJO DE PASIVOS LABORALES
A4: Objetivo:
B5: Verificar la correcta imputación en las cuentas contables respectivas , de los pasivos laborales generados durante todo el período bajo análisis como así tambien la imputación de los pagos correspondientes , verificando el saldo pendiente de pago al cierre.
A8: PROCEDIMIENTO para completar este papel de Trabajo:
A10: 1.- | B10: Completar la pestaña títulos con los datos de la empresa.
A11: 2.- | B11: Copiar en pestaña SyS el Sys de la empresa
A12: 3.- | B12: Analisis General > Colocar los periodos correspondente al ejercicio de analisis. Y completar planilla con relevamiento de 931
A13: 4.- | B13: Bajar desde pagina de AFIP las Retenciones a contribuciones sociales y pegarlas en Hoja "Ret SUSS" desde fila 25 hacia abajo respetando que coincidan los titulos con los datos pegados
A14: 5.- | B14: Bajar desde la pagina de AFIP los Pagos realizados en el ejericio y pegarlo en hoja "Pagos" desde fila 5 hacia abajo respetando titulos. De Igual forma los pagos posteriores desde Fila 5 Col K
A15: 6.- | B15: Importante > En punto 4 y 5 los importes se deben convertir a numero o reemplazar . (punto de texto) por , (coma) para que lol tome como numero
A16: 7.- | B16: Tabla de Pagos > Ubicados A5 seleccionar "Actualizar datos" y desde H5 lo mismo
A17: 8.- | B17: Completar Hoja Compensaciones.
A18: 9.- | B18: Saldo Inicio y Cierre > se analizan las cuentas patrimoniales incluidas en el 931. Se debe vinculas con la hoja "Tabla Pagos" para analizar pasivos

Sheet Cuentas Auditadas
H1: #VALUE!
B6: EMPRESA: | C6: =Títulos!B2 -> 0 | D6: CUENTAS A AUDITAR
B7: INICIO | C7: =Títulos!B3 -> 45658
B8: CIERRE | C8: =Títulos!B4 -> 46022
F10: Ajustes Totales a proponer | H10: =+SUM(H14:H25) -> 0
A13: Ajuste | B13: Código | C13: Descripción | D13: Importe SyS | E13: Saldo auditado | F13: Desvio en valores | G13: Desvio en % | H13: Ajuste Propuesto | I13: Observaciones
F14: =+E14-D14 -> 0 | G14: =+IF(F14<>0,F14/D14,0) -> 0 | H14: =+VALUE(IFERROR(IF(A14="SI",F14,0),"")) -> 0
F15: =+E15-D15 -> 0 | G15: =+IF(F15<>0,F15/D15,0) -> 0 | H15: =+VALUE(IFERROR(IF(A15="SI",F15,0),"")) -> 0
F16: =+E16-D16 -> 0 | G16: =+IF(F16<>0,F16/D16,0) -> 0 | H16: =+VALUE(IFERROR(IF(A16="SI",F16,0),"")) -> 0
F17: =+E17-D17 -> 0 | G17: =+IF(F17<>0,F17/D17,0) -> 0 | H17: =+VALUE(IFERROR(IF(A17="SI",F17,0),"")) -> 0
F18: =+E18-D18 -> 0 | G18: =+IF(F18<>0,F18/D18,0) -> 0 | H18: =+VALUE(IFERROR(IF(A18="SI",F18,0),"")) -> 0
F19: =+E19-D19 -> 0 | G19: =+IF(F19<>0,F19/D19,0) -> 0 | H19: =+VALUE(IFERROR(IF(A19="SI",F19,0),"")) -> 0
F20: =+E20-D20 -> 0 | G20: =+IF(F20<>0,F20/D20,0) -> 0 | H20: =+VALUE(IFERROR(IF(A20="SI",F20,0),"")) -> 0
F21: =+E21-D21 -> 0 | G21: =+IF(F21<>0,F21/D21,0) -> 0 | H21: =+VALUE(IFERROR(IF(A21="SI",F21,0),"")) -> 0
F22: =+E22-D22 -> 0 | G22: =+IF(F22<>0,F22/D22,0) -> 0 | H22: =+VALUE(IFERROR(IF(A22="SI",F22,0),"")) -> 0
F23: =+E23-D23 -> 0 | G23: =+IF(F23<>0,F23/D23,0) -> 0 | H23: =+VALUE(IFERROR(IF(A23="SI",F23,0),"")) -> 0
F24: =+E24-D24 -> 0 | G24: =+IF(F24<>0,F24/D24,0) -> 0 | H24: =+VALUE(IFERROR(IF(A24="SI",F24,0),"")) -> 0
F25: =+E25-D25 -> 0 | G25: =+IF(F25<>0,F25/D25,0) -> 0 | H25: =+VALUE(IFERROR(IF(A25="SI",F25,0),"")) -> 0

Sheet Sys
B2: CÓDIGO | C2: CUENTA | D2: SALDO
B688: X | C688: X | D688: X

Sheet Analisis General
B2: EMPRESA: | C2: =Títulos!B2 -> 0 | D2: =+#REF! -> #REF!
B3: FECHA DE LA AUDITORÍA: | C3: =Títulos!F2 -> 0 | D3: =+#REF! -> #REF!
B4: AUDITORIA AL: | C4: =Títulos!B4 -> 46022 | D4: =+#REF! -> #REF!
B6: ANÁLISIS F931 | Q6: Saldos Contab. | R6: Diferencia
B7: CONCEPTO | D7: =EOMONTH(E7,-1) -> 45688 | E7: =EOMONTH(F7,-1) -> 45716 | F7: =EOMONTH(G7,-1) -> 45747 | G7: =EOMONTH(H7,-1) -> 45777 | H7: =EOMONTH(I7,-1) -> 45808 | I7: =EOMONTH(J7,-1) -> 45838 | J7: =EOMONTH(K7,-1) -> 45869 | K7: =EOMONTH(L7,-1) -> 45900 | ... N7: =EOMONTH(O7,-1) -> 45991 | O7: =Títulos!B4 -> 46022 | P7: TOTALES
B8: ORIGINAL / RECTIFICATIVA | D8: =IF('931'!E4="Orig. (0) - Rect. (1/9): 0","Original","Rectificativa") -> Rectificativa | E8: =IF('931'!M4="Orig. (0) - Rect. (1/9): 0","Original","Rectificativa") -> Rectificativa | F8: =IF('931'!U4="Orig. (0) - Rect. (1/9): 0","Original","Rectificativa") -> Rectificativa | G8: =IF('931'!AC4="Orig. (0) - Rect. (1/9): 0","Original","Rectificativa") -> Rectificativa | H8: =IF('931'!AK4="Orig. (0) - Rect. (1/9): 0","Original","Rectificativa") -> Rectificativa | I8: =IF('931'!AS4="Orig. (0) - Rect. (1/9): 0","Original","Rectificativa") -> Rectificativa | J8: =IF('931'!BA4="Orig. (0) - Rect. (1/9): 0","Original","Rectificativa") -> Rectificativa | K8: =IF('931'!BI4="Orig. (0) - Rect. (1/9): 0","Original","Rectificativa") -> Rectificativa | L8: =IF('931'!BQ4="Orig. (0) - Rect. (1/9): 0","Original","Rectificativa") -> Rectificativa | M8: =IF('931'!BY4="Orig. (0) - Rect. (1/9): 0","Original","Rectificativa") -> Rectificativa | N8: =IF('931'!CG4="Orig. (0) - Rect. (1/9): 0","Original","Rectificativa") -> Rectificativa | O8: =IF('931'!CO4="Orig. (0) - Rect. (1/9): 0","Original","Rectificativa") -> Rectificativa
B9: CANTIDAD DE EMPLEADOS | D9: ='931'!F6 -> 0 | E9: ='931'!N6 -> 0 | F9: ='931'!V6 -> 0 | G9: ='931'!AD6 -> 0 | H9: ='931'!AL6 -> 0 | I9: ='931'!AT6 -> 0 | J9: ='931'!BB6 -> 0 | K9: ='931'!BJ6 -> 0 | L9: ='931'!BR6 -> 0 | M9: ='931'!BZ6 -> 0 | N9: ='931'!CH6 -> 0 | O9: ='931'!CP6 -> 0
B10: FECHA DE PRESENTACIÓN | D10: ='931'!D5 -> 0 | E10: ='931'!L5 -> 0 | F10: ='931'!T5 -> 0 | G10: ='931'!AB5 -> 0 | H10: ='931'!AJ5 -> 0 | I10: ='931'!AR5 -> 0 | J10: ='931'!AZ5 -> 0 | K10: ='931'!BH5 -> 0 | L10: ='931'!BP5 -> 0 | M10: ='931'!BX5 -> 0 | N10: ='931'!CF5 -> 0 | O10: ='931'!CN5 -> 0
B11: REMUNERACIÓN 2 | D11: ='931'!F8 -> 0 | E11: ='931'!N8 -> 0 | F11: ='931'!V8 -> 0 | G11: ='931'!AD8 -> 0 | H11: ='931'!AL8 -> 0 | I11: ='931'!AT8 -> 0 | J11: ='931'!BB8 -> 0 | K11: ='931'!BJ8 -> 0 | L11: ='931'!BR8 -> 0 | M11: ='931'!BZ8 -> 0 | N11: ='931'!CH8 -> 0 | O11: ='931'!CP8 -> 0 | P11: =SUM(D11:O11) -> 0
B12: CONCEPTOS NO REMUNERATIVOS | P12: =SUM(D12:O12) -> 0
B13: REMUNERACIÓN 10 | D13: ='931'!F16 -> 0 | E13: ='931'!N16 -> 0 | F13: ='931'!V16 -> 0 | G13: ='931'!AD16 -> 0 | H13: ='931'!AL16 -> 0 | I13: ='931'!AT16 -> 0 | J13: ='931'!BB16 -> 0 | K13: ='931'!BJ16 -> 0 | L13: ='931'!BR16 -> 0 | M13: ='931'!BZ16 -> 0 | N13: ='931'!CH16 -> 0 | O13: ='931'!CP16 -> 0 | P13: =SUM(D13:O13) -> 0
B14: APORTES SUSS | D14: ='931'!D19 -> 0 | E14: ='931'!L19 -> 0 | F14: ='931'!T19 -> 0 | G14: ='931'!AB19 -> 0 | H14: ='931'!AJ19 -> 0 | I14: ='931'!AR19 -> 0 | J14: ='931'!AZ19 -> 0 | K14: ='931'!BH19 -> 0 | L14: ='931'!BP19 -> 0 | M14: ='931'!BX19 -> 0 | N14: ='931'!CF19 -> 0 | O14: ='931'!CN19 -> 0
B15: APORTES A FAVOR | D15: ='931'!D20 -> 0 | E15: ='931'!L20 -> 0 | F15: ='931'!T20 -> 0 | G15: ='931'!AB20 -> 0 | H15: ='931'!AJ20 -> 0 | I15: ='931'!AR20 -> 0 | J15: ='931'!AZ20 -> 0 | K15: ='931'!BH20 -> 0 | L15: ='931'!BP20 -> 0 | M15: ='931'!BX20 -> 0 | N15: ='931'!CF20 -> 0 | O15: ='931'!CN20 -> 0
B16: APORTES SEG. SOCIAL A PAGAR | D16: =+D14-D15 -> 0 | E16: =+E14-E15 -> 0 | F16: =+F14-F15 -> 0 | G16: =+G14-G15 -> 0 | H16: =+H14-H15 -> 0 | I16: =+I14-I15 -> 0 | J16: =+J14-J15 -> 0 | K16: =+K14-K15 -> 0 | ... O16: =+O14-O15 -> 0 | P16: =SUM(D16:O16) -> 0
B17: CONTRIBUCIONES SUSS | D17: ='931'!D24 -> 0 | E17: ='931'!L24 -> 0 | F17: ='931'!T24 -> 0 | G17: ='931'!AB24 -> 0 | H17: ='931'!AJ24 -> 0 | I17: ='931'!AR24 -> 0 | J17: ='931'!AZ24 -> 0 | K17: ='931'!BH24 -> 0 | L17: ='931'!BP24 -> 0 | M17: ='931'!BX24 -> 0 | N17: ='931'!CF24 -> 0 | O17: ='931'!CN24 -> 0
B18: EXCEDENTES CONT. A FAVOR | D18: ='931'!D25 -> 0 | E18: ='931'!L25 -> 0 | F18: ='931'!T25 -> 0 | G18: ='931'!AB25 -> 0 | H18: ='931'!AJ25 -> 0 | I18: ='931'!AR25 -> 0 | J18: ='931'!AZ25 -> 0 | K18: ='931'!BH25 -> 0 | L18: ='931'!BP25 -> 0 | M18: ='931'!BX25 -> 0 | N18: ='931'!CF25 -> 0 | O18: ='931'!CN25 -> 0
B19: DETRACCIÓN ART. 23 LEY 27.541 | D19: ='931'!D26 -> 0 | E19: ='931'!L26 -> 0 | F19: ='931'!T26 -> 0 | G19: ='931'!AB26 -> 0 | H19: ='931'!AJ26 -> 0 | I19: ='931'!AR26 -> 0 | J19: ='931'!AZ26 -> 0 | K19: ='931'!BH26 -> 0 | L19: ='931'!BP26 -> 0 | M19: ='931'!BX26 -> 0 | N19: ='931'!CF26 -> 0 | O19: ='931'!CN26 -> 0
B20: RETENCIONES | D20: ='931'!D29 -> 0 | E20: ='931'!L29 -> 0 | F20: ='931'!T29 -> 0 | G20: ='931'!AB29 -> 0 | H20: ='931'!AJ29 -> 0 | I20: ='931'!AR29 -> 0 | J20: ='931'!AZ29 -> 0 | K20: ='931'!BH29 -> 0 | L20: ='931'!BP29 -> 0 | M20: ='931'!BX29 -> 0 | N20: ='931'!CF29 -> 0 | O20: ='931'!CN29 -> 0
B21: CONTRIBUCIONES SEG. SOCIAL A PAGAR | D21: =+D17-D18-D19-D20 -> 0 | E21: =+E17-E18-E19-E20 -> 0 | F21: =+F17-F18-F19-F20 -> 0 | G21: =+G17-G18-G19-G20 -> 0 | H21: =+H17-H18-H19-H20 -> 0 | I21: =+I17-I18-I19-I20 -> 0 | J21: =+J17-J18-J19-J20 -> 0 | K21: =+K17-K18-K19-K20 -> 0 | ... O21: =+O17-O18-O19-O20 -> 0 | P21: =SUM(D21:O21) -> 0
B22: OTROS (EJ. CONTRIBUCIONES RENATRE) | P22: =SUM(D22:O22) -> 0
B23: OTROS (EJ. SEG. SEPELIO UATRE) | P23: =SUM(D23:O23) -> 0
B24: APORTES O.S. | D24: ='931'!H19 -> 0 | E24: ='931'!P19 -> 0 | F24: ='931'!X19 -> 0 | G24: ='931'!AF19 -> 0 | H24: ='931'!AN19 -> 0 | I24: ='931'!AV19 -> 0 | J24: ='931'!BD19 -> 0 | K24: ='931'!BL19 -> 0 | L24: ='931'!BT19 -> 0 | M24: ='931'!CB19 -> 0 | N24: ='931'!CJ19 -> 0 | O24: ='931'!CR19 -> 0
B25: APORTES A FAVOR | D25: ='931'!H20 -> 0 | E25: ='931'!P20 -> 0 | F25: ='931'!X20 -> 0 | G25: ='931'!AF20 -> 0 | H25: ='931'!AN20 -> 0 | I25: ='931'!AV20 -> 0 | J25: ='931'!BD20 -> 0 | K25: ='931'!BL20 -> 0 | L25: ='931'!BT20 -> 0 | M25: ='931'!CB20 -> 0 | N25: ='931'!CJ20 -> 0 | O25: ='931'!CR20 -> 0
B26: APORTES OBRA SOCIAL A PAGAR | D26: =+D24-D25 -> 0 | E26: =+E24-E25 -> 0 | F26: =+F24-F25 -> 0 | G26: =+G24-G25 -> 0 | H26: =+H24-H25 -> 0 | I26: =+I24-I25 -> 0 | J26: =+J24-J25 -> 0 | K26: =+K24-K25 -> 0 | ... O26: =+O24-O25 -> 0 | P26: =SUM(D26:O26) -> 0
B27: CONTRIBUCIONES O.S. | D27: ='931'!H23 -> 0 | E27: ='931'!P23 -> 0 | F27: ='931'!X23 -> 0 | G27: ='931'!AF23 -> 0 | H27: ='931'!AN23 -> 0 | I27: ='931'!AV23 -> 0 | J27: ='931'!BD23 -> 0 | K27: ='931'!BL23 -> 0 | L27: ='931'!BT23 -> 0 | M27: ='931'!CB23 -> 0 | N27: ='931'!CJ23 -> 0 | O27: ='931'!CR23 -> 0
B28: EXCEDENTES CONT. A FAVOR | D28: ='931'!H24 -> 0 | E28: ='931'!P24 -> 0 | F28: ='931'!X24 -> 0 | G28: ='931'!AF24 -> 0 | H28: ='931'!AN24 -> 0 | I28: ='931'!AV24 -> 0 | J28: ='931'!BD24 -> 0 | K28: ='931'!BL24 -> 0 | L28: ='931'!BT24 -> 0 | M28: ='931'!CB24 -> 0 | N28: ='931'!CJ24 -> 0 | O28: ='931'!CR24 -> 0
B29: RETENCIONES | D29: ='931'!H27 -> 0 | E29: ='931'!P27 -> 0 | F29: ='931'!X27 -> 0 | G29: ='931'!AF27 -> 0 | H29: ='931'!AN27 -> 0 | I29: ='931'!AV27 -> 0 | J29: ='931'!BD27 -> 0 | K29: ='931'!BL27 -> 0 | L29: ='931'!BT27 -> 0 | M29: ='931'!CB27 -> 0 | N29: ='931'!CJ27 -> 0 | O29: ='931'!CR27 -> 0
B30: CONTIBUCIONES OBRA SOCIAL A PAGAR | D30: =+D27-D28-D29 -> 0 | E30: =+E27-E28-E29 -> 0 | F30: =+F27-F28-F29 -> 0 | G30: =+G27-G28-G29 -> 0 | H30: =+H27-H28-H29 -> 0 | I30: =+I27-I28-I29 -> 0 | J30: =+J27-J28-J29 -> 0 | K30: =+K27-K28-K29 -> 0 | ... O30: =+O27-O28-O29 -> 0 | P30: =SUM(D30:O30) -> 0
B31: ART | D31: ='931'!D44 -> 0 | E31: ='931'!L44 -> 0 | F31: ='931'!T44 -> 0 | G31: ='931'!AB44 -> 0 | H31: ='931'!AJ44 -> 0 | I31: ='931'!AR44 -> 0 | J31: ='931'!AZ44 -> 0 | K31: ='931'!BH44 -> 0 | L31: ='931'!BP44 -> 0 | M31: ='931'!BX44 -> 0 | N31: ='931'!CF44 -> 0 | O31: ='931'!CN44 -> 0 | P31: =SUM(D31:O31) -> 0
B32: SEGURO DE VIDA COLECTIVO OBLIGATORIO | D32: ='931'!H44 -> 0 | E32: ='931'!P44 -> 0 | F32: ='931'!X44 -> 0 | G32: ='931'!AF44 -> 0 | H32: ='931'!AN44 -> 0 | I32: ='931'!AV44 -> 0 | J32: ='931'!BD44 -> 0 | K32: ='931'!BL44 -> 0 | L32: ='931'!BT44 -> 0 | M32: ='931'!CB44 -> 0 | N32: ='931'!CJ44 -> 0 | O32: ='931'!CK44 -> 0 | P32: =SUM(D32:O32) -> 0
B33: TOTAL 931 | D33: =+D16+D21+D31+D26+D30+D32+D22+D23 -> 0 | E33: =+E16+E21+E31+E26+E30+E32+E22+E23 -> 0 | F33: =+F16+F21+F31+F26+F30+F32+F22+F23 -> 0 | G33: =+G16+G21+G31+G26+G30+G32+G22+G23 -> 0 | H33: =+H16+H21+H31+H26+H30+H32+H22+H23 -> 0 | I33: =+I16+I21+I31+I26+I30+I32+I22+I23 -> 0 | J33: =+J16+J21+J31+J26+J30+J32+J22+J23 -> 0 | K33: =+K16+K21+K31+K26+K30+K32+K22+K23 -> 0 | ... O33: =+O16+O21+O31+O26+O30+O32+O22+O23 -> 0 | P33: =SUM(D33:O33) -> 0
B34: FACYS (Descontado del bono) | P34: =SUM(D34:O34) -> 0
B35: CEC (Descontado del bono) | P35: =SUM(D35:O35) -> 0
B36: CUOTA ALIMENTARIA (Descontada del bono)
B37: SINDICATO 4 (Contribución) | P37: =SUM(D37:O37) -> 0
B38: COSTO TOTAL PARA LA EMPRESA | D38: =+D11+D12+D17-D18+D27-D28+D32+D31+D37 -> 0 | E38: =+E11+E12+E17-E18+E27-E28+E32+E31+E37 -> 0 | F38: =+F11+F12+F17-F18+F27-F28+F32+F31+F37 -> 0 | G38: =+G11+G12+G17-G18+G27-G28+G32+G31+G37 -> 0 | H38: =+H11+H12+H17-H18+H27-H28+H32+H31+H37 -> 0 | I38: =+I11+I12+I17-I18+I27-I28+I32+I31+I37 -> 0 | J38: =+J11+J12+J17-J18+J27-J28+J32+J31+J37 -> 0 | K38: =+K11+K12+K17-K18+K27-K28+K32+K31+K37 -> 0 | ... O38: =+O11+O12+O17-O18+O27-O28+O32+O31+O37 -> 0 | P38: =SUM(D38:O38) -> 0 | Q38: =+D54 -> 0 | R38: =(+Q38-P38)/Q38 -> #DIV/0!
B41: CUENTAS DE RESULTADO
B42: Código | C42: Desccripción | D42: Saldo | E42: S. Auditado | F42: Desvío | G42: Observaciones
D43: =IFERROR(VLOOKUP(B43,Sys!$C$3:$E$4667,3,FALSE),0) -> 0 | F43: =+D43-E43 -> 0
D44: =IFERROR(VLOOKUP(B44,Sys!$C$3:$E$4667,3,FALSE),0) -> 0 | F44: =+D44-E44 -> 0
...

Sheet 931
B1: =MONTH(Títulos!B3) -> 1 | J1: =IF(B1=12,1,B1+1) -> 2 | R1: =IF(J1=12,1,J1+1) -> 3 | Z1: =IF(R1=12,1,R1+1) -> 4 | AH1: =IF(Z1=12,1,Z1+1) -> 5 | AP1: =IF(AH1=12,1,AH1+1) -> 6 | AX1: =IF(AP1=12,1,AP1+1) -> 7 | BF1: =IF(AX1=12,1,AX1+1) -> 8 | BN1: =IF(BF1=12,1,BF1+1) -> 9 | BV1: =IF(BN1=12,1,BN1+1) -> 10 | CD1: =IF(BV1=12,1,BV1+1) -> 11 | CL1: =IF(CD1=12,1,CD1+1) -> 12

Sheet Saldo Inicio y cierre
B1: ANALISIS DE PASIVOS LABORALES
B2: EMPRESA: | C2: =Títulos!B2 -> 0 | D2: =+#REF! -> #REF!
B3: FECHA DE LA AUDITORÍA: | C3: =Títulos!F2 -> 0 | D3: =+#REF! -> #REF!
B4: AUDITORIA AL: | C4: =Títulos!B4 -> 46022 | D4: =+#REF! -> #REF!
B7: PASIVO LABORAL - SALDOS AL INICIO
B9: CUENTAS PATRIMONIALES
B10: Código | C10: Desccripción | D10: Saldos S/ Balance Anterior | E10: PAGO | F10: Pendiente de cancelacion | G10: He observado comprobante de pago (SI/NO) | H10: Medio de pago utilizado | I10: Observaciones
D11: =IFERROR(VLOOKUP(B11,#REF!,3,FALSE),0) -> 0 | F11: =+D11-E11 -> 0
D12: =IFERROR(VLOOKUP(B12,#REF!,3,FALSE),0) -> 0 | F12: =+D12-E12 -> 0
D13: =IFERROR(VLOOKUP(B13,#REF!,3,FALSE),0) -> 0 | F13: =+D13-E13 -> 0
D14: =IFERROR(VLOOKUP(B14,#REF!,3,FALSE),0) -> 0 | F14: =+D14-E14 -> 0
D15: =IFERROR(VLOOKUP(B15,#REF!,3,FALSE),0) -> 0 | F15: =+D15-E15 -> 0
D16: =IFERROR(VLOOKUP(B16,#REF!,3,FALSE),0) -> 0 | F16: =+D16-E16 -> 0
D17: =IFERROR(VLOOKUP(B17,#REF!,3,FALSE),0) -> 0 | F17: =+D17-E17 -> 0
B20: PASIVO LABORAL - SALDOS AL CIERRE
B22: PERIODO | C22: =TEXT('Analisis General'!D7,"MM") -> 01 | D22: =TEXT('Analisis General'!E7,"MM") -> 02 | E22: =TEXT('Analisis General'!F7,"MM") -> 03 | F22: =TEXT('Analisis General'!G7,"MM") -> 04 | G22: =TEXT('Analisis General'!H7,"MM") -> 05 | H22: =TEXT('Analisis General'!I7,"MM") -> 06 | I22: =TEXT('Analisis General'!J7,"MM") -> 07 | J22: =TEXT('Analisis General'!K7,"MM") -> 08 | ... N22: =TEXT('Analisis General'!O7,"MM") -> 12 | O22: TOTAL
B23: TOTAL 931 | C23: =+'Analisis General'!D33 -> 0 | D23: =+'Analisis General'!E33 -> 0 | E23: =+'Analisis General'!F33 -> 0 | F23: =+'Analisis General'!G33 -> 0 | G23: =+'Analisis General'!H33 -> 0 | H23: =+'Analisis General'!I33 -> 0 | I23: =+'Analisis General'!J33 -> 0 | J23: =+'Analisis General'!K33 -> 0 | ... N23: =+'Analisis General'!O33 -> 0 | O23: =SUM(C23:N23) -> 0
B25: PAGOS VEP | O25: =SUM(C25:N25) -> 0
B26: PLANES DE PAGOS | C26: =SUMIF(COMPENSACIONES!$B5:$B1064,'Saldo Inicio y cierre'!C$22,COMPENSACIONES!$F5:$F1065) -> 0 | D26: =SUMIF(COMPENSACIONES!$B5:$B1064,'Saldo Inicio y cierre'!D$22,COMPENSACIONES!$F5:$F1065) -> 0 | E26: =SUMIF(COMPENSACIONES!$B5:$B1064,'Saldo Inicio y cierre'!E$22,COMPENSACIONES!$F5:$F1065) -> 0 | F26: =SUMIF(COMPENSACIONES!$B5:$B1064,'Saldo Inicio y cierre'!F$22,COMPENSACIONES!$F5:$F1065) -> 0 | G26: =SUMIF(COMPENSACIONES!$B5:$B1064,'Saldo Inicio y cierre'!G$22,COMPENSACIONES!$F5:$F1065) -> 0 | H26: =SUMIF(COMPENSACIONES!$B5:$B1064,'Saldo Inicio y cierre'!H$22,COMPENSACIONES!$F5:$F1065) -> 0 | I26: =SUMIF(COMPENSACIONES!$B5:$B1064,'Saldo Inicio y cierre'!I$22,COMPENSACIONES!$F5:$F1065) -> 0 | J26: =SUMIF(COMPENSACIONES!$B5:$B1064,'Saldo Inicio y cierre'!J$22,COMPENSACIONES!$F5:$F1065) -> 0 | ... N26: =SUMIF(COMPENSACIONES!$B5:$B1064,'Saldo Inicio y cierre'!N$22,COMPENSACIONES!$F5:$F1065) -> 0 | O26: =SUM(C26:N26) -> 0
B27: COMPENSACION IDYCB | O27: =SUM(C27:N27) -> 0
B29: SALDO | C29: =+C23-C25-C26-C27 -> 0 | D29: =+D23-D25-D26-D27 -> 0 | E29: =+E23-E25-E26-E27 -> 0 | F29: =+F23-F25-F26-F27 -> 0 | G29: =+G23-G25-G26-G27 -> 0 | H29: =+H23-H25-H26-H27 -> 0 | I29: =+I23-I25-I26-I27 -> 0 | J29: =+J23-J25-J26-J27 -> 0 | ... N29: =+N23-N25-N26-N27 -> 0 | O29: =SUM(C29:N29) -> 0
B32: CUENTAS PATRIMONIALES 931
B33: Código | C33: Desccripción | D33: Saldo SyS | E33: Saldos s/ Auditoria | F33: Desvio Ctas Patrimoniales | G33: He observado comprobante de pago posterior (SI/NO) | H33: Medio de pago utilizado | I33: Observaciones
D34: =IFERROR(VLOOKUP(B34,Sys!$C$3:$E$10167,3,FALSE),0) -> 0 | F34: =+D34-E34 -> 0
D35: =IFERROR(VLOOKUP(B35,Sys!$C$3:$E$10167,3,FALSE),0) -> 0 | F35: =+D35-E35 -> 0
D36: =IFERROR(VLOOKUP(B36,Sys!$C$3:$E$10167,3,FALSE),0) -> 0 | F36: =+D36-E36 -> 0
D37: =IFERROR(VLOOKUP(B37,Sys!$C$3:$E$10167,3,FALSE),0) -> 0 | F37: =+D37-E37 -> 0
D38: =IFERROR(VLOOKUP(B38,Sys!$C$3:$E$10167,3,FALSE),0) -> 0 | F38: =+D38-E38 -> 0
D39: =IFERROR(VLOOKUP(B39,Sys!$C$3:$E$10167,3,FALSE),0) -> 0 | F39: =+D39-E39 -> 0
D40: =IFERROR(VLOOKUP(B40,Sys!$C$3:$E$10167,3,FALSE),0) -> 0 | F40: =+D40-E40 -> 0
D41: =SUM(D34:D40) -> 0 | E41: =SUM(E34:E40) -> 0 | F41: =(+D41-E41)/D41 -> #DIV/0!
B43: Pagos desde la tabla de pagos
B45: OBLIGACION | C45: =+C22 -> 01 | D45: =+D22 -> 02 | E45: =+E22 -> 03 | F45: =+F22 -> 04 | G45: =+G22 -> 05 | H45: =+H22 -> 06 | I45: =+I22 -> 07 | J45: =+J22 -> 08 | ... O45: =+O22 -> TOTAL
B47: APORTES SEG. SOCIAL A PAGAR | C47: =+'Analisis General'!D16 -> 0 | D47: =+'Analisis General'!E16 -> 0 | E47: =+'Analisis General'!F16 -> 0 | F47: =+'Analisis General'!G16 -> 0 | G47: =+'Analisis General'!H16 -> 0 | H47: =+'Analisis General'!I16 -> 0 | I47: =+'Analisis General'!J16 -> 0 | J47: =+'Analisis General'!K16 -> 0 | ... N47: =+'Analisis General'!O16 -> 0 | O47: =SUM(C47:N47) -> 0
B48: PAGO | O48: =SUM(C48:N48) -> 0
B49: CONTRIBUCIONES SEG. SOCIAL A PAGAR | C49: =+'Analisis General'!D21 -> 0 | D49: =+'Analisis General'!E21 -> 0 | E49: =+'Analisis General'!F21 -> 0 | F49: =+'Analisis General'!G21 -> 0 | G49: =+'Analisis General'!H21 -> 0 | H49: =+'Analisis General'!I21 -> 0 | I49: =+'Analisis General'!J21 -> 0 | J49: =+'Analisis General'!K21 -> 0 | ... N49: =+'Analisis General'!O21 -> 0 | O49: =SUM(C49:N49) -> 0
B50: PAGO | O50: =SUM(C50:N50) -> 0
B51: APORTES OBRA SOCIAL A PAGAR | C51: =+'Analisis General'!D26 -> 0 | D51: =+'Analisis General'!E26 -> 0 | E51: =+'Analisis General'!F26 -> 0 | F51: =+'Analisis General'!G26 -> 0 | G51: =+'Analisis General'!H26 -> 0 | H51: =+'Analisis General'!I26 -> 0 | I51: =+'Analisis General'!J26 -> 0 | J51: =+'Analisis General'!K26 -> 0 | ... N51: =+'Analisis General'!O26 -> 0 | O51: =SUM(C51:N51) -> 0
B52: PAGO | O52: =SUM(C52:N52) -> 0
B53: CONTIBUCIONES OBRA SOCIAL A PAGAR | C53: =+'Analisis General'!D30 -> 0 | D53: =+'Analisis General'!E30 -> 0 | E53: =+'Analisis General'!F30 -> 0 | F53: =+'Analisis General'!G30 -> 0 | G53: =+'Analisis General'!H30 -> 0 | H53: =+'Analisis General'!I30 -> 0 | I53: =+'Analisis General'!J30 -> 0 | J53: =+'Analisis General'!K30 -> 0 | ... N53: =+'Analisis General'!O30 -> 0 | O53: =SUM(C53:N53) -> 0
...

Sheet Ret. SUSS
B1: ANÁLISIS RETENCIONES SUSS
B2: EMPRESA: | C2: =Títulos!B2 -> 0 | D2: =+#REF! -> #REF!
B3: FECHA DE LA AUDITORÍA: | C3: =Títulos!F2 -> 0 | D3: =+#REF! -> #REF!
B4: AUDITORIA AL: | C4: =Títulos!B4 -> 46022 | D4: =+#REF! -> #REF!
B10: PERIODO | C10: =TEXT('Analisis General'!D$7,"mm") -> 01 | D10: =TEXT('Analisis General'!E$7,"mm") -> 02 | E10: =TEXT('Analisis General'!F$7,"mm") -> 03 | F10: =TEXT('Analisis General'!G$7,"mm") -> 04 | G10: =TEXT('Analisis General'!H$7,"mm") -> 05 | H10: =TEXT('Analisis General'!I$7,"mm") -> 06 | I10: =TEXT('Analisis General'!J$7,"mm") -> 07 | J10: =TEXT('Analisis General'!K$7,"mm") -> 08 | ... N10: =TEXT('Analisis General'!O$7,"mm") -> 12
B12: Declaradas en AFIP | C12: =SUMIF($O25:$O246,C$10,$L25:$L247) -> 0 | D12: =SUMIF($O25:$O246,D$10,$L25:$L247) -> 0 | E12: =SUMIF($O25:$O246,E$10,$L25:$L247) -> 0 | F12: =SUMIF($O25:$O246,F$10,$L25:$L247) -> 0 | G12: =SUMIF($O25:$O246,G$10,$L25:$L247) -> 0 | H12: =SUMIF($O25:$O246,H$10,$L25:$L247) -> 0 | I12: =SUMIF($O25:$O246,I$10,$L25:$L247) -> 0 | J12: =SUMIF($O25:$O246,J$10,$L25:$L247) -> 0 | ... N12: =SUMIF($O25:$O246,N$10,$L25:$L247) -> 0
B14: Tomadas en 931 | C14: =+'Analisis General'!D20+'Analisis General'!D29 -> 0 | D14: =+'Analisis General'!E20+'Analisis General'!E29 -> 0 | E14: =+'Analisis General'!F20+'Analisis General'!F29 -> 0 | F14: =+'Analisis General'!G20+'Analisis General'!G29 -> 0 | G14: =+'Analisis General'!H20+'Analisis General'!H29 -> 0 | H14: =+'Analisis General'!I20+'Analisis General'!I29 -> 0 | I14: =+'Analisis General'!J20+'Analisis General'!J29 -> 0 | J14: =+'Analisis General'!K20+'Analisis General'!K29 -> 0 | ... N14: =+'Analisis General'!O20+'Analisis General'!O29 -> 0 | O14: =SUM(C14:N14) -> 0
B16: No tomadas (Credito) | C16: =+C12-C14 -> 0 | D16: =+D12-D14 -> 0 | E16: =+E12-E14 -> 0 | F16: =+F12-F14 -> 0 | G16: =+G12-G14 -> 0 | H16: =+H12-H14 -> 0 | I16: =+I12-I14 -> 0 | J16: =+J12-J14 -> 0 | ... N16: =+N12-N14 -> 0 | O16: =SUM(C16:N16) -> 0
B18: Saldo s/ Auditoría | C18: =+C16 -> 0 | D18: =+D16 -> 0 | E18: =+E16 -> 0 | F18: =+F16 -> 0 | G18: =+G16 -> 0 | H18: =+H16 -> 0 | I18: =+I16 -> 0 | J18: =+J16 -> 0 | ... N18: =+N16 -> 0 | O18: =SUM(C18:N18) -> 0
B20: Saldo s/ Contabilidad
B22: Diferencia | C22: =+C20-C18 -> 0 | D22: =+D20-D18 -> 0 | E22: =+E20-E18 -> 0 | F22: =+F20-F18 -> 0 | G22: =+G20-G18 -> 0 | H22: =+H20-H18 -> 0 | I22: =+I20-I18 -> 0 | J22: =+J20-J18 -> 0 | ... O22: =+O20-O18 -> 0
B24: CUIT Agente Ret./Perc. | C24: Denominación o Razón Social | D24: Impuesto | E24: Descripción Impuesto | F24: Régimen | G24: Descripción Régimen | H24: Fecha Ret./Perc. | I24: Número Certificado | J24: Descripción Operación | K24: Importe Ret./Perc. | L24: Importe Excedente | M24: Total | N24: Fecha Ingreso | O24: MES
O25: =+TEXT(H25,"MM") -> 01
O26: =+TEXT(H26,"MM") -> 01
O27: =+TEXT(H27,"MM") -> 01
O28: =+TEXT(H28,"MM") -> 01
O29: =+TEXT(H29,"MM") -> 01
O30: =+TEXT(H30,"MM") -> 01
O31: =+TEXT(H31,"MM") -> 01
O32: =+TEXT(H32,"MM") -> 01
O33: =+TEXT(H33,"MM") -> 01
O34: =+TEXT(H34,"MM") -> 01
O35: =+TEXT(H35,"MM") -> 01
O36: =+TEXT(H36,"MM") -> 01
... O3680: =+TEXT(H3680,"MM") -> 01

Sheet PAGOS
A2: DURANTE EL EJERCICIO | K2: POSTERIOR AL EJERICIO | U2: COMPENSACIONES CON F931
A4: Fecha Operación | B4: Formulario | C4: Version | D4: Impuesto | E4: Periodo | F4: Importe | G4: Observaciones | K4: Fecha Operación | L4: Formulario | M4: Version | N4: Impuesto | O4: Periodo | P4: Importe | Q4: Observaciones | U4: Fecha Operación
U6: ='Analisis General'!D7 -> 45688
U7: =EOMONTH(U6,1) -> 45716
U8: =EOMONTH(U7,1) -> 45747
U9: =EOMONTH(U8,1) -> 45777
U10: =EOMONTH(U9,1) -> 45808
U11: =EOMONTH(U10,1) -> 45838
U12: =EOMONTH(U11,1) -> 45869
U13: =EOMONTH(U12,1) -> 45900
U14: =EOMONTH(U13,1) -> 45930
U15: =EOMONTH(U14,1) -> 45961
U16: =EOMONTH(U15,1) -> 45991
U17: =EOMONTH(U16,1) -> 46022

Sheet TABLA PAGOS
A2: DURANTE EL EJERCICIO | H2: POSTERIOR AL EJERICIO
A5: Etiquetas de fila | B5: Suma de Importe | H5: Etiquetas de fila | I5: Suma de Importe
A6: (en blanco) | H6: (en blanco)
A7: (en blanco) | H7: Total general
A8: (en blanco)
A9: Total general

Sheet COMPENSACIONES
B4: MES | C4: Periodo | D4: Banco | E4: CBU | F4: Importe Compensado
B5: =TEXT(C5,"MM") -> 01
B6: =TEXT(C6,"MM") -> 01
B7: =TEXT(C7,"MM") -> 01
B8: =TEXT(C8,"MM") -> 01
B9: =TEXT(C9,"MM") -> 01
B10: =TEXT(C10,"MM") -> 01
B11: =TEXT(C11,"MM") -> 01
B12: =TEXT(C12,"MM") -> 01
B13: =TEXT(C13,"MM") -> 01
B14: =TEXT(C14,"MM") -> 01
B15: =TEXT(C15,"MM") -> 01
B16: =TEXT(C16,"MM") -> 01
... B2179: =TEXT(C2179,"MM") -> 01

Sheet D.814
C2: EMPRESA: | D2: =+#REF! -> #REF! | L2: =+Resumen!E13 -> P. LABORAL 6
C3: FECHA DE LA AUDITORÍA: | D3: =+#REF! -> #REF!
C4: AUDITORIA AL: | D4: =+#REF! -> #REF!
C6: CÁLCULO DEL CRÉDITO FISCAL - DTO. 814
C8: Saldo tomado en la DDJJ de IVA | D8: =+'Analisis General'!D7 -> 45688 | E8: =+'Analisis General'!E7 -> 45716 | F8: =+'Analisis General'!F7 -> 45747 | G8: =+'Analisis General'!G7 -> 45777 | H8: =+'Analisis General'!H7 -> 45808 | I8: =+'Analisis General'!I7 -> 45838 | J8: =+'Analisis General'!J7 -> 45869 | K8: =+'Analisis General'!K7 -> 45900 | ... O8: =+'Analisis General'!O7 -> 46022 | P8: TOTAL
C9: Contribuciones Seg Soc (Dto. 814/2001) | D9: =+'Analisis General'!#REF! -> #REF! | E9: =+'Analisis General'!#REF! -> #REF! | F9: =+'Analisis General'!#REF! -> #REF! | G9: =+'Analisis General'!#REF! -> #REF! | H9: =+'Analisis General'!#REF! -> #REF! | I9: =+'Analisis General'!#REF! -> #REF! | J9: =+'Analisis General'!#REF! -> #REF! | K9: =+'Analisis General'!#REF! -> #REF! | ... O9: =+'Analisis General'!#REF! -> #REF! | P9: =SUM(D9:O9) -> #REF!
C11: Período | D11: =+D8 -> 45688 | E11: =+E8 -> 45716 | F11: =+F8 -> 45747 | G11: =+G8 -> 45777 | H11: =+H8 -> 45808 | I11: =+I8 -> 45838 | J11: =+J8 -> 45869 | K11: =+K8 -> 45900 | ... O11: =+O8 -> 46022 | P11: TOTAL
C12: Base de Cálculo | D12: =+'Analisis General'!D13 -> 0 | E12: =+'Analisis General'!E13 -> 0 | F12: =+'Analisis General'!F13 -> 0 | G12: =+'Analisis General'!G13 -> 0 | H12: =+'Analisis General'!H13 -> 0 | I12: =+'Analisis General'!I13 -> 0 | J12: =+'Analisis General'!J13 -> 0 | K12: =+'Analisis General'!K13 -> 0 | ... O12: =+'Analisis General'!O13 -> 0
C13: Porcentaje (varía según zona) | D13: 0.03 | E13: 0.03 | F13: 0.03 | G13: 0.03 | H13: 0.03 | I13: 0.03 | J13: 0.03 | K13: 0.03 | L13: 0.03 | M13: 0.03 | N13: 0.03 | O13: 0.03
C14: Importe determinado según porcentaje | D14: =+D12*D13 -> 0 | E14: =+E12*E13 -> 0 | F14: =+F12*F13 -> 0 | G14: =+G12*G13 -> 0 | H14: =+H12*H13 -> 0 | I14: =+I12*I13 -> 0 | J14: =+J12*J13 -> 0 | K14: =+K12*K13 -> 0 | ... O14: =+O12*O13 -> 0
C15: Fecha de cancelación del formulario 931
C16: Diferencia | D16: =+D9-D14 -> #REF! | E16: =+E9-E14 -> #REF! | F16: =+F9-F14 -> #REF! | G16: =+G9-G14 -> #REF! | H16: =+H9-H14 -> #REF! | I16: =+I9-I14 -> #REF! | J16: =+J9-J14 -> #REF! | K16: =+K9-K14 -> #REF! | ... O16: =+O9-O14 -> #REF! | P16: =SUM(D16:O16) -> #REF!
C17: % de desvío | D17: =+D16/D9 -> #REF! | E17: =+E16/E9 -> #REF! | F17: =+F16/F9 -> #REF! | G17: =+G16/G9 -> #REF! | H17: =+H16/H9 -> #REF! | I17: =+I16/I9 -> #REF! | J17: =+J16/J9 -> #REF! | K17: =+K16/K9 -> #REF! | ... O17: =+O16/O9 -> #REF!
C18: Conclusión
D23: =+#REF! -> #REF! | L23: =+#REF! -> #REF!
D24: =LEFT(#REF!,7) -> #REF! | L24: =LEFT(#REF!,10) -> #REF!

Sheet Cuestionario
B2: EMPRESA: | C2: =+#REF! -> #REF! | F2: =+Resumen!E24 -> P. LABORAL 10
B3: FECHA DE LA AUDITORÍA: | C3: =+#REF! -> #REF!
B4: AUDITORIA AL: | C4: =+#REF! -> #REF!
B6: CUESTIONARIOS - PASIVOS LABORALES
B8: Lugar y Fecha de Emisión Informe: | F8: Lugar, xx de xx de xxxx
B10: Encuestado: | F10: NOMBRE DEL ENTREVISTADO
B12: Emisor: | F12: NOMBRE DEL AUDITOR A CARGO
B15: EXAMEN DE CONTROLES | C15: SI | D15: NO | E15: N/A | F15: COMENTARIOS
B17: 1. Se encuentran segregadas las funciones de: a) control de servicios; b) liquidación de retribuciones; c) pago de retribuciones; d) en su caso, conciliación de cuentas bancarias para pago de haberes?
B18: 2. Existen una clara definición de funciones y atribución de responsabilidades?
B19: 3. Existen normas escritas referentes al procedimiento de haberes y cargas sociales?
B20: 4. Se mantiene un archivo actualizado de las diferentes disposiciones legales y reglamentarias relativas a remuneraciones y cargas sociales?
B21: 5. Existen legajos individuales por empleado en el que consten todos los antecedentes necesarios para una correcta liquidación de haberes?
B22: 6. Se controlan los tiempos trabajados y los no trabajados pero remunerados, quedando constancia escrita de ello?
B23: 7. Se autorizan horas extras?
B24: 8. Existe información básica confiable que permita liquidar las comisiones sobre ventas, cobranzas, etc.?
B25: 9. Existe independencia entre los siguientes sectores: liquidación de haberes; control de servicios y pago de remuneraciones?
B26: 10. Se revisan por persona independiente de quien las prepara, las liquidaciones individuales y las nóminas generales, tanto desde el punto de vista cuantitativo como cualitativo?
B27: 11. Se autorizan las planillas de remuneraciones por un nivel superior al que las prepara?
B28: 12. En el momento de pago se exige la identificación del beneficiario?
... B72: 40. Existen arreglos de sueldos con los empleados por fuera de lo que establecen los convenios?
B75: =+F10 -> NOMBRE DEL ENTREVISTADO | F75: =+F12 -> NOMBRE DEL AUDITOR A CARGO
B76: Responsable | F76: Auditor

Sheet Mayores
A2: EMPRESA: | C2: =+#REF! -> #REF! | F2: =+Resumen!E12 -> P. LABORAL 5
A3: FECHA DE LA AUDITORÍA: | C3: =+#REF! -> #REF!
A4: AUDITORIA AL: | C4: =+#REF! -> #REF!
A6: MAYORES CONTABLES

Sheet Resumen
B2: EMPRESA: | C2: =+#REF! -> #REF!
B3: FECHA DE LA AUDITORÍA: | C3: =+#REF! -> #REF!
B4: AUDITORIA AL: | C4: =+#REF! -> #REF!
B5: PASIVO LABORAL
B6: DESCRIPCIÓN | C6: ESTADO (OK-EN PROCESO-OBSERVADO - N/C) | D6: COMENTARIO | E6: REF
B7: ¿Se realizó la selección de las cuentas a auditar y se propusieron los ajustes de auditoría? | E7: P. LABORAL 1
B8: ¿Se realizó el control de los saldos iniciales? Correspondencia con el último balance certificado, cancelación posterior. | E8: P. LABORAL 2
B9: ¿Se realizó el control cruzado del formulario 931 vs. Cuentas de resultado y asientos contables? | E9: P. LABORAL 3
B10: ¿Se realizó el control de los saldos finales y los pagos posteriores a la fecha de cierre? | E10: P. LABORAL 4
B11: ¿Se realizó el control cruzado de vep vs cuentas tributarias y asientos contables de la ART y la obra social? | E11: =+E10 -> P. LABORAL 4
B12: ¿Se hizo la revisión de los mayores contables? Devengamiento mensual de deuda y pago. | E12: P. LABORAL 5
B13: ¿Se realizó la revisión aritmética del cálculo del crédito fiscal cargas sociales? (Decreto 814) | E13: P. LABORAL 6
B14: ¿Se realizó el control cruzado de retenciones computadas en F931 y Mis Retenciones? | E14: P. LABORAL 7
B15: ¿Se revisaron los beneficios recibidos? (ATP-REPRO) | E15: P. LABORAL 8
B16: Control de retenciones de Impuesto a las Ganancias correspondientes a la 4º Categoría
B17: VERIFICACIÓN DE DOCUMENTACIÓN REGLAMENTARIA:
B18: - libros de sueldos rubricados, transcriptos y encuadernados.
B19: - planilla de control horario rubricadas y firmadas.
B20: - recibos de sueldos firmados
B21: REVISIÓN PROVISIÓN DE VACACIONES, SAC, MULTAS Y/O JUICIOS LABORALES.
B22: COTEJAR LOS SALDOS DE LOS PLANES DE PAGOS SOCIALES CON LA CONTABILIDAD
B23: Circularización a los asesores legales vs provisión de juicios laborales contabilizados | E23: P. LABORAL 9
B24: ¿Se completó el cuestionario? | E24: P. LABORAL 10
B25: ¿Se completó el memorándum de conclusiones? | E25: P. LABORAL 11
B26: Carga de la composición final en el inventario.
C30: =+#REF! -> #REF! | D30: =+#REF! -> #REF!
